<?xml version="1.0" encoding="utf-8"?>
<!-- This URDF was automatically created by SolidWorks to URDF Exporter! Originally created by Stephen Brawner (brawner@gmail.com) 
     Commit Version: 1.6.0-4-g7f85cfe  Build Version: 1.6.7995.38578
     For more information, please see http://wiki.ros.org/sw_urdf_exporter -->
<robot
  name="cx_arm">
  <link
    name="base_link">
    <inertial>
      <origin
        xyz="-8.57785426963895E-06 2.91685088001456E-11 -0.000974489333363107"
        rpy="0 0 0" />
      <mass
        value="4.32625731944912" />
      <inertia
        ixx="0.00936193290592399"
        ixy="-2.41377958548306E-11"
        ixz="1.11730024887402E-06"
        iyy="0.00464359195689199"
        iyz="3.91172397325664E-12"
        izz="0.00881969682014568" />
    </inertial>
    <visual>
      <origin
        xyz="0 0 0"
        rpy="0 0 0" />
      <geometry>
        <mesh
          filename="package://cx_arm/meshes/base_link.STL" />
      </geometry>
      <material
        name="">
        <color
          rgba="0.898039215686275 0.917647058823529 0.929411764705882 1" />
      </material>
    </visual>
    <collision>
      <origin
        xyz="0 0 0"
        rpy="0 0 0" />
      <geometry>
        <mesh
          filename="package://cx_arm/meshes/base_link.STL" />
      </geometry>
    </collision>
  </link>
  <link
    name="Link101">
    <inertial>
      <origin
        xyz="3.09073246348727E-19 0.0311194583357993 -0.0313358876222972"
        rpy="0 0 0" />
      <mass
        value="0.308135455569499" />
      <inertia
        ixx="0.00036301532443775"
        ixy="-4.85280379528671E-20"
        ixz="1.31350202954282E-19"
        iyy="0.000311071590986095"
        iyz="-9.08288552069947E-05"
        izz="0.000308601623909284" />
    </inertial>
    <visual>
      <origin
        xyz="0 0 0"
        rpy="0 0 0" />
      <geometry>
        <mesh
          filename="package://cx_arm/meshes/Link101.STL" />
      </geometry>
      <material
        name="">
        <color
          rgba="0.898039215686275 0.917647058823529 0.929411764705882 1" />
      </material>
    </visual>
    <collision>
      <origin
        xyz="0 0 0"
        rpy="0 0 0" />
      <geometry>
        <mesh
          filename="package://cx_arm/meshes/Link101.STL" />
      </geometry>
    </collision>
  </link>
  <joint
    name="joint101"
    type="revolute">
    <origin
      xyz="0 0.241 0"
      rpy="0 -1.5708 -1.5708" />
    <parent
      link="base_link" />
    <child
      link="Link101" />
    <axis
      xyz="0 0 -1" />
    <limit
      lower="-3.14"
      upper="3.14"
      effort="100"
      velocity="1" />
  </joint>
  <link
    name="Link102">
    <inertial>
      <origin
        xyz="6.55817899986033E-11 0.0474740262124326 -0.000349231545579993"
        rpy="0 0 0" />
      <mass
        value="2.69736870589475" />
      <inertia
        ixx="0.0030082793755842"
        ixy="3.60652165853059E-11"
        ixz="-5.40640934400988E-11"
        iyy="0.0025464770034934"
        iyz="4.37126407123363E-05"
        izz="0.00284907972609921" />
    </inertial>
    <visual>
      <origin
        xyz="0 0 0"
        rpy="0 0 0" />
      <geometry>
        <mesh
          filename="package://cx_arm/meshes/Link102.STL" />
      </geometry>
      <material
        name="">
        <color
          rgba="0.898039215686275 0.917647058823529 0.929411764705882 1" />
      </material>
    </visual>
    <collision>
      <origin
        xyz="0 0 0"
        rpy="0 0 0" />
      <geometry>
        <mesh
          filename="package://cx_arm/meshes/Link102.STL" />
      </geometry>
    </collision>
  </link>
  <joint
    name="joint102"
    type="revolute">
    <origin
      xyz="0 0 0"
      rpy="0 1.5708 1.5708" />
    <parent
      link="Link101" />
    <child
      link="Link102" />
    <axis
      xyz="0 0 1" />
    <limit
      lower="-3.14"
      upper="3.14"
      effort="100"
      velocity="1" />
  </joint>
  <link
    name="Link103">
    <inertial>
      <origin
        xyz="0.00403786373486228 -8.5540454944355E-07 -0.110448513050592"
        rpy="0 0 0" />
      <mass
        value="0.542683241876569" />
      <inertia
        ixx="0.00196275066135883"
        ixy="1.20230059837595E-08"
        ixz="-0.000106647178605952"
        iyy="0.00182891010022251"
        iyz="-9.87744488589856E-08"
        izz="0.000634630066974942" />
    </inertial>
    <visual>
      <origin
        xyz="0 0 0"
        rpy="0 0 0" />
      <geometry>
        <mesh
          filename="package://cx_arm/meshes/Link103.STL" />
      </geometry>
      <material
        name="">
        <color
          rgba="0.898039215686275 0.917647058823529 0.929411764705882 1" />
      </material>
    </visual>
    <collision>
      <origin
        xyz="0 0 0"
        rpy="0 0 0" />
      <geometry>
        <mesh
          filename="package://cx_arm/meshes/Link103.STL" />
      </geometry>
    </collision>
  </link>
  <joint
    name="joint103"
    type="revolute">
    <origin
      xyz="0 0.31051 0"
      rpy="-1.5708 -1.5708 0" />
    <parent
      link="Link102" />
    <child
      link="Link103" />
    <axis
      xyz="0 0 1" />
    <limit
      lower="-3.14"
      upper="3.14"
      effort="100"
      velocity="1" />
  </joint>
  <link
    name="Link104">
    <inertial>
      <origin
        xyz="-0.0106288742525643 0.00774461275266647 2.27423330168008E-09"
        rpy="0 0 0" />
      <mass
        value="0.108256528066753" />
      <inertia
        ixx="4.03178186223482E-05"
        ixy="-5.57671127233385E-07"
        ixz="7.06454927788419E-12"
        iyy="5.26215340888357E-05"
        iyz="-6.91116952457739E-12"
        izz="4.11256800739082E-05" />
    </inertial>
    <visual>
      <origin
        xyz="0 0 0"
        rpy="0 0 0" />
      <geometry>
        <mesh
          filename="package://cx_arm/meshes/Link104.STL" />
      </geometry>
      <material
        name="">
        <color
          rgba="0.898039215686275 0.917647058823529 0.929411764705882 1" />
      </material>
    </visual>
    <collision>
      <origin
        xyz="0 0 0"
        rpy="0 0 0" />
      <geometry>
        <mesh
          filename="package://cx_arm/meshes/Link104.STL" />
      </geometry>
    </collision>
  </link>
  <joint
    name="joint104"
    type="revolute">
    <origin
      xyz="0.0125 0 0"
      rpy="1.5708 0 0" />
    <parent
      link="Link103" />
    <child
      link="Link104" />
    <axis
      xyz="0 0 -1" />
    <limit
      lower="-3.14"
      upper="3.14"
      effort="100"
      velocity="1" />
  </joint>
  <link
    name="Link105">
    <inertial>
      <origin
        xyz="0.00133867533735108 -2.520780639825E-07 -0.136878436349784"
        rpy="0 0 0" />
      <mass
        value="0.823764981510393" />
      <inertia
        ixx="0.000805503567246632"
        ixy="4.34642990628367E-09"
        ixz="-3.4217286340017E-05"
        iyy="0.000788139498917337"
        iyz="2.41350428188773E-08"
        izz="0.000520088884504294" />
    </inertial>
    <visual>
      <origin
        xyz="0 0 0"
        rpy="0 0 0" />
      <geometry>
        <mesh
          filename="package://cx_arm/meshes/Link105.STL" />
      </geometry>
      <material
        name="">
        <color
          rgba="0.898039215686275 0.917647058823529 0.929411764705882 1" />
      </material>
    </visual>
    <collision>
      <origin
        xyz="0 0 0"
        rpy="0 0 0" />
      <geometry>
        <mesh
          filename="package://cx_arm/meshes/Link105.STL" />
      </geometry>
    </collision>
  </link>
  <joint
    name="joint105"
    type="revolute">
    <origin
      xyz="-0.0125 0.20712 0"
      rpy="-1.5708 1.5708 0" />
    <parent
      link="Link104" />
    <child
      link="Link105" />
    <axis
      xyz="0 0 1" />
    <limit
      lower="-3.14"
      upper="3.14"
      effort="100"
      velocity="1" />
  </joint>
  <link
    name="Link106">
    <inertial>
      <origin
        xyz="-0.0147561154984304 0.115479110569376 -1.14344406730722E-08"
        rpy="0 0 0" />
      <mass
        value="1.03484290276942" />
      <inertia
        ixx="0.00380934495195938"
        ixy="5.37470018645263E-06"
        ixz="-7.18789559007885E-11"
        iyy="0.000540685574036727"
        iyz="-3.26010155413101E-10"
        izz="0.00341220175694068" />
    </inertial>
    <visual>
      <origin
        xyz="0 0 0"
        rpy="0 0 0" />
      <geometry>
        <mesh
          filename="package://cx_arm/meshes/Link106.STL" />
      </geometry>
      <material
        name="">
        <color
          rgba="0.898039215686275 0.917647058823529 0.929411764705882 1" />
      </material>
    </visual>
    <collision>
      <origin
        xyz="0 0 0"
        rpy="0 0 0" />
      <geometry>
        <mesh
          filename="package://cx_arm/meshes/Link106.STL" />
      </geometry>
    </collision>
  </link>
  <joint
    name="joint106"
    type="revolute">
    <origin
      xyz="0.015 0 0"
      rpy="1.5708 0 0" />
    <parent
      link="Link105" />
    <child
      link="Link106" />
    <axis
      xyz="0 0 -1" />
    <limit
      lower="-3.14"
      upper="3.14"
      effort="100"
      velocity="1" />
  </joint>
  <link
    name="Link201">
    <inertial>
      <origin
        xyz="-1.84414916847598E-17 0.0311194583357994 0.0313358876222972"
        rpy="0 0 0" />
      <mass
        value="0.308135455569499" />
      <inertia
        ixx="0.00036301532443775"
        ixy="-6.93176639822126E-20"
        ixz="5.27454345175039E-20"
        iyy="0.000311071590986095"
        iyz="9.08288552069948E-05"
        izz="0.000308601623909284" />
    </inertial>
    <visual>
      <origin
        xyz="0 0 0"
        rpy="0 0 0" />
      <geometry>
        <mesh
          filename="package://cx_arm/meshes/Link201.STL" />
      </geometry>
      <material
        name="">
        <color
          rgba="0.898039215686275 0.917647058823529 0.929411764705882 1" />
      </material>
    </visual>
    <collision>
      <origin
        xyz="0 0 0"
        rpy="0 0 0" />
      <geometry>
        <mesh
          filename="package://cx_arm/meshes/Link201.STL" />
      </geometry>
    </collision>
  </link>
  <joint
    name="joint201"
    type="revolute">
    <origin
      xyz="0 -0.241 0"
      rpy="0 -1.5708 -1.5708" />
    <parent
      link="base_link" />
    <child
      link="Link201" />
    <axis
      xyz="0 0 -1" />
    <limit
      lower="-3.14"
      upper="3.14"
      effort="100"
      velocity="1" />
  </joint>
  <link
    name="Link202">
    <inertial>
      <origin
        xyz="6.55818455097545E-11 0.0474740262124326 -0.00034923154558"
        rpy="0 0 0" />
      <mass
        value="2.69736870589475" />
      <inertia
        ixx="0.0030082793755842"
        ixy="3.60652161984646E-11"
        ixz="-5.40640933809016E-11"
        iyy="0.0025464770034934"
        iyz="4.37126407123364E-05"
        izz="0.00284907972609921" />
    </inertial>
    <visual>
      <origin
        xyz="0 0 0"
        rpy="0 0 0" />
      <geometry>
        <mesh
          filename="package://cx_arm/meshes/Link202.STL" />
      </geometry>
      <material
        name="">
        <color
          rgba="0.898039215686275 0.917647058823529 0.929411764705882 1" />
      </material>
    </visual>
    <collision>
      <origin
        xyz="0 0 0"
        rpy="0 0 0" />
      <geometry>
        <mesh
          filename="package://cx_arm/meshes/Link202.STL" />
      </geometry>
    </collision>
  </link>
  <joint
    name="joint202"
    type="revolute">
    <origin
      xyz="0 0 0"
      rpy="0 1.5708 1.5708" />
    <parent
      link="Link201" />
    <child
      link="Link202" />
    <axis
      xyz="0 0 -1" />
    <limit
      lower="-3.14"
      upper="3.14"
      effort="100"
      velocity="1" />
  </joint>
  <link
    name="Link203">
    <inertial>
      <origin
        xyz="0.00403786373486148 -8.55404549082728E-07 -0.110448513050592"
        rpy="0 0 0" />
      <mass
        value="0.542683241876568" />
      <inertia
        ixx="0.00196275066135882"
        ixy="1.20230059850405E-08"
        ixz="-0.00010664717860595"
        iyy="0.0018289101002225"
        iyz="-9.87744488602046E-08"
        izz="0.000634630066974935" />
    </inertial>
    <visual>
      <origin
        xyz="0 0 0"
        rpy="0 0 0" />
      <geometry>
        <mesh
          filename="package://cx_arm/meshes/Link203.STL" />
      </geometry>
      <material
        name="">
        <color
          rgba="0.898039215686275 0.917647058823529 0.929411764705882 1" />
      </material>
    </visual>
    <collision>
      <origin
        xyz="0 0 0"
        rpy="0 0 0" />
      <geometry>
        <mesh
          filename="package://cx_arm/meshes/Link203.STL" />
      </geometry>
    </collision>
  </link>
  <joint
    name="joint203"
    type="revolute">
    <origin
      xyz="0 0.31051 0"
      rpy="-1.5708 -1.5708 0" />
    <parent
      link="Link202" />
    <child
      link="Link203" />
    <axis
      xyz="0 0 -1" />
    <limit
      lower="-3.14"
      upper="3.14"
      effort="100"
      velocity="1" />
  </joint>
  <link
    name="Link204">
    <inertial>
      <origin
        xyz="-0.0106288743285585 0.00774461276828292 2.53762266755331E-09"
        rpy="0 0 0" />
      <mass
        value="0.108256528509688" />
      <inertia
        ixx="4.03178186913715E-05"
        ixy="-5.57671090684546E-07"
        ixz="7.66559441988123E-12"
        iyy="5.26215343038913E-05"
        iyz="-7.06238638861397E-12"
        izz="4.11256802411633E-05" />
    </inertial>
    <visual>
      <origin
        xyz="0 0 0"
        rpy="0 0 0" />
      <geometry>
        <mesh
          filename="package://cx_arm/meshes/Link204.STL" />
      </geometry>
      <material
        name="">
        <color
          rgba="0.898039215686275 0.917647058823529 0.929411764705882 1" />
      </material>
    </visual>
    <collision>
      <origin
        xyz="0 0 0"
        rpy="0 0 0" />
      <geometry>
        <mesh
          filename="package://cx_arm/meshes/Link204.STL" />
      </geometry>
    </collision>
  </link>
  <joint
    name="joint204"
    type="revolute">
    <origin
      xyz="0.0125 0 0"
      rpy="1.5708 0 0" />
    <parent
      link="Link203" />
    <child
      link="Link204" />
    <axis
      xyz="0 0 -1" />
    <limit
      lower="-3.14"
      upper="3.14"
      effort="100"
      velocity="1" />
  </joint>
  <link
    name="Link205">
    <inertial>
      <origin
        xyz="-0.00133867533735096 2.52078064112103E-07 -0.136878436349784"
        rpy="0 0 0" />
      <mass
        value="0.823764981510393" />
      <inertia
        ixx="0.00080550356724663"
        ixy="4.34642990674269E-09"
        ixz="3.42172863400182E-05"
        iyy="0.000788139498917335"
        iyz="-2.41350428190537E-08"
        izz="0.000520088884504294" />
    </inertial>
    <visual>
      <origin
        xyz="0 0 0"
        rpy="0 0 0" />
      <geometry>
        <mesh
          filename="package://cx_arm/meshes/Link205.STL" />
      </geometry>
      <material
        name="">
        <color
          rgba="0.898039215686275 0.917647058823529 0.929411764705882 1" />
      </material>
    </visual>
    <collision>
      <origin
        xyz="0 0 0"
        rpy="0 0 0" />
      <geometry>
        <mesh
          filename="package://cx_arm/meshes/Link205.STL" />
      </geometry>
    </collision>
  </link>
  <joint
    name="joint205"
    type="revolute">
    <origin
      xyz="-0.0125 0.20712 0"
      rpy="-1.5708 1.5708 0" />
    <parent
      link="Link204" />
    <child
      link="Link205" />
    <axis
      xyz="0 0 -1" />
    <limit
      lower="-3.14"
      upper="3.14"
      effort="100"
      velocity="1" />
  </joint>
  <link
    name="Link206">
    <inertial>
      <origin
        xyz="0.0147561154984302 0.115479110569376 1.14344406596036E-08"
        rpy="0 0 0" />
      <mass
        value="1.03484290276942" />
      <inertia
        ixx="0.00380934495195937"
        ixy="-5.37470018645118E-06"
        ixz="-7.18789559471613E-11"
        iyy="0.000540685574036725"
        iyz="3.26010156822639E-10"
        izz="0.00341220175694067" />
    </inertial>
    <visual>
      <origin
        xyz="0 0 0"
        rpy="0 0 0" />
      <geometry>
        <mesh
          filename="package://cx_arm/meshes/Link206.STL" />
      </geometry>
      <material
        name="">
        <color
          rgba="0.898039215686275 0.917647058823529 0.929411764705882 1" />
      </material>
    </visual>
    <collision>
      <origin
        xyz="0 0 0"
        rpy="0 0 0" />
      <geometry>
        <mesh
          filename="package://cx_arm/meshes/Link206.STL" />
      </geometry>
    </collision>
  </link>
  <joint
    name="joint206"
    type="revolute">
    <origin
      xyz="-0.015 0 0"
      rpy="1.5708 0 0" />
    <parent
      link="Link205" />
    <child
      link="Link206" />
    <axis
      xyz="0 0 1" />
    <limit
      lower="-3.14"
      upper="3.14"
      effort="100"
      velocity="1" />
  </joint>
</robot>
