<mujoco model="cx_arm">

  <compiler angle="radian" meshdir="/home/u/CXDL/code/git/CXDL_ROS_main/src/CXDL_ROS/cx_description/meshes" autolimits="true"/>

  <asset>
    <mesh name="base_link" file="base_link.STL"/>
    <mesh name="Link101" file="Link101.STL"/>
    <mesh name="Link102" file="Link102.STL"/>
    <mesh name="Link103" file="Link103.STL"/>
    <mesh name="Link104" file="Link104.STL"/>
    <mesh name="Link105" file="Link105.STL"/>
    <mesh name="Link106" file="Link106.STL"/>
    <mesh name="Link201" file="Link201.STL"/>
    <mesh name="Link202" file="Link202.STL"/>
    <mesh name="Link203" file="Link203.STL"/>
    <mesh name="Link204" file="Link204.STL"/>
    <mesh name="Link205" file="Link205.STL"/>
    <mesh name="Link206" file="Link206.STL"/>
  </asset>

  <worldbody>
    <geom type="mesh" contype="0" conaffinity="0" group="1" density="0" rgba="0.89804 0.91765 0.92941 1" mesh="base_link"/>
    <geom type="mesh" rgba="0.89804 0.91765 0.92941 1" mesh="base_link"/>
    <body name="Link101" pos="0 0.241 0" quat="0.499998 -0.5 -0.5 -0.500002">
      <inertial pos="0 0.0311195 -0.0313359" quat="0.654197 -0.268376 0.268376 0.654197" mass="0.308135" diaginertia="0.000400674 0.000363015 0.000218999"/>
      <joint name="joint101" pos="0 0 0" axis="0 0 1" range="-3.14 3.14"/>
      <geom type="mesh" contype="0" conaffinity="0" group="1" density="0" rgba="0.898039 0.917647 0.929412 1" mesh="Link101"/>
      <geom type="mesh" rgba="0.898039 0.917647 0.929412 1" mesh="Link101"/>
      <body name="Link102" quat="0.5 0.5 -0.5 0.5">
        <inertial pos="-6.55817e-11 -0.047474 -0.000349232" quat="0.655682 0.755038 0 0" mass="2.69737" diaginertia="0.00300828 0.00285527 0.00254029"/>
        <joint name="joint102" pos="0 0 0" axis="0 0 1" range="-3.14 3.14"/>
        <geom type="mesh" contype="0" conaffinity="0" group="1" density="0" rgba="0.898039 0.917647 0.929412 1" mesh="Link102"/>
        <geom type="mesh" rgba="0.898039 0.917647 0.929412 1" mesh="Link102"/>
        <body name="Link103" pos="0 -0.310333 0" quat="0.503563 0.496411 0.496411 -0.503563">
          <inertial pos="0.00246383 -8.55405e-07 -0.110317" quat="0.998899 -3.72183e-05 0.0469223 7.15161e-05" mass="0.542683" diaginertia="0.00197126 0.00182891 0.000626121"/>
          <joint name="joint103" pos="0 0 0" axis="0.0142591 0 0.999898" range="-3.14 3.14"/>
          <geom type="mesh" contype="0" conaffinity="0" group="1" density="0" rgba="0.898039 0.917647 0.929412 1" mesh="Link103"/>
          <geom type="mesh" rgba="0.898039 0.917647 0.929412 1" mesh="Link103"/>
          <body name="Link104" pos="0.0125 0 0" quat="0.707089 -0.707089 0.00504148 0.00504148">
            <inertial pos="-0.00973407 -0.00841588 -2.83551e-09" quat="0.483364 0.483362 0.5161 0.516102" mass="0.102219" diaginertia="4.7433e-05 3.7948e-05 3.56148e-05"/>
            <joint name="joint104" pos="0 0 0" axis="0 0 1" range="-3.14 3.14"/>
            <geom type="mesh" contype="0" conaffinity="0" group="1" density="0" rgba="0.898039 0.917647 0.929412 1" mesh="Link104"/>
            <geom type="mesh" rgba="0.898039 0.917647 0.929412 1" mesh="Link104"/>
            <body name="Link105" pos="-0.0154456 -0.206469 0" quat="0.496422 0.503552 -0.496422 0.503552">
              <inertial pos="0.00133195 -2.55653e-07 -0.13643" quat="0.99827 4.70011e-05 0.0587986 2.38878e-05" mass="0.823765" diaginertia="0.000809546 0.000788137 0.000516044"/>
              <joint name="joint105" pos="0 0 0" axis="0 0 -1" range="-3.14 3.14"/>
              <geom type="mesh" contype="0" conaffinity="0" group="1" density="0" rgba="0.898039 0.917647 0.929412 1" mesh="Link105"/>
              <geom type="mesh" rgba="0.898039 0.917647 0.929412 1" mesh="Link105"/>
              <body name="Link106" pos="0.0149933 0 0.000448917" quat="0.702047 0.71213 0 0">
                <inertial pos="-0.0182055 0.114974 -0.00163961" quat="0.712041 0.70196 0.0112426 0.0110833" mass="1.03484" diaginertia="0.00380935 0.0034122 0.000540676"/>
                <joint name="joint106" pos="0 0 0" axis="0 -0.0142591 -0.999898" range="-3.14 3.14"/>
                <geom type="mesh" contype="0" conaffinity="0" group="1" density="0" rgba="0.898039 0.917647 0.929412 1" mesh="Link106"/>
                <geom type="mesh" rgba="0.898039 0.917647 0.929412 1" mesh="Link106"/>
              </body>
            </body>
          </body>
        </body>
      </body>
    </body>
    <body name="Link201" pos="0 -0.241 0" quat="0.499998 -0.5 -0.5 -0.500002">
      <inertial pos="0 0 0" quat="0.707107 0.707107 0 0" mass="4.3273" diaginertia="0.0093675 0.0088256 0.0046459"/>
      <joint name="joint201" pos="0 0 0" axis="0 0 -1" range="-3.14 3.14"/>
      <geom type="mesh" contype="0" conaffinity="0" group="1" density="0" rgba="1 1 1 1" mesh="Link201"/>
      <geom type="mesh" rgba="1 1 1 1" mesh="Link201"/>
      <body name="Link202" quat="0.5 0.5 -0.5 0.5">
        <inertial pos="-6.55818e-11 -0.047474 -0.000349232" quat="0.655682 0.755038 0 0" mass="2.69737" diaginertia="0.00300828 0.00285527 0.00254029"/>
        <joint name="joint202" pos="0 0 0" axis="0 0 1" range="-3.14 3.14"/>
        <geom type="mesh" contype="0" conaffinity="0" group="1" density="0" rgba="0.898039 0.917647 0.929412 1" mesh="Link202"/>
        <geom type="mesh" rgba="0.898039 0.917647 0.929412 1" mesh="Link202"/>
        <body name="Link203" pos="0 -0.310026 0" quat="0.509616 0.490196 0.490196 -0.509616">
          <inertial pos="-0.000244759 -8.55405e-07 -0.110037" quat="0.998246 -3.63365e-05 0.0591963 7.19681e-05" mass="0.542683" diaginertia="0.00197126 0.00182891 0.000626121"/>
          <joint name="joint203" pos="0 0 0" axis="0.0388326 0 0.999246" range="-3.14 3.14"/>
          <geom type="mesh" contype="0" conaffinity="0" group="1" density="0" rgba="0.898039 0.917647 0.929412 1" mesh="Link203"/>
          <geom type="mesh" rgba="0.898039 0.917647 0.929412 1" mesh="Link203"/>
          <body name="Link204" pos="0.0125 0 0" quat="0.706973 -0.706973 0.013732 0.013732">
            <inertial pos="-0.009938 -0.00817407 -2.95815e-09" quat="0.489671 0.489669 0.51012 0.510122" mass="0.102219" diaginertia="4.7433e-05 3.7948e-05 3.56148e-05"/>
            <joint name="joint204" pos="0 0 0" axis="0 0 1" range="-3.14 3.14"/>
            <geom type="mesh" contype="0" conaffinity="0" group="1" density="0" rgba="0.898039 0.917647 0.929412 1" mesh="Link204"/>
            <geom type="mesh" rgba="0.898039 0.917647 0.929412 1" mesh="Link204"/>
            <body name="Link205" pos="-0.0205161 -0.206027 0" quat="0.490196 0.509616 -0.490196 0.509616">
              <inertial pos="-0.00133197 2.43084e-07 -0.136429" quat="0.99827 -4.6812e-05 -0.0587982 5.40874e-05" mass="0.823766" diaginertia="0.000809556 0.000788146 0.000516044"/>
              <joint name="joint205" pos="0 0 0" axis="0 0 -1" range="-3.14 3.14"/>
              <geom type="mesh" contype="0" conaffinity="0" group="1" density="0" rgba="0.898039 0.917647 0.929412 1" mesh="Link205"/>
              <geom type="mesh" rgba="0.898039 0.917647 0.929412 1" mesh="Link205"/>
              <body name="Link206" pos="-0.0149933 0 0.000448917" quat="0.693241 0.720705 0 0">
                <inertial pos="0.0182055 0.114899 -0.00446518" quat="0.720616 0.693155 -0.0113782 -0.0109446" mass="1.03484" diaginertia="0.00380935 0.0034122 0.000540676"/>
                <joint name="joint206" pos="0 0 0" axis="0 0.0388326 0.999246" range="-3.14 3.14"/>
                <geom type="mesh" contype="0" conaffinity="0" group="1" density="0" rgba="0.898039 0.917647 0.929412 1" mesh="Link206"/>
                <geom type="mesh" rgba="0.898039 0.917647 0.929412 1" mesh="Link206"/>
              </body>
            </body>
          </body>
        </body>
      </body>
    </body>
  </worldbody>






  <actuator>
    <motor joint="joint101" name ="torque101" ctrllimited="true" ctrlrange="-3.14 3.14" gear="1"/>
    <position name ="pservo101" joint ="joint101" kp="100"/>
    <velocity name ="vservo101" joint ="joint101" kv="0.1"/>

    <motor joint="joint102" name ="torque102" ctrllimited="true" ctrlrange="-3.14 3.14" gear="1"/>
    <position name ="pservo102" joint ="joint102" kp="100"/>
    <velocity name ="vservo102" joint ="joint102" kv="10"/>
    
    <motor joint="joint103" name ="torque103" ctrllimited="true" ctrlrange="-3.14 3.14" gear="1"/>
    <position name ="pservo103" joint ="joint103" kp="100"/>
    <velocity name ="vservo103" joint ="joint103" kv="0.1"/>
    
    <motor joint="joint104" name ="torque104" ctrllimited="true" ctrlrange="-3.14 3.14" gear="1"/>
    <position name ="pervo104" joint ="joint104" kp="100"/>
    <velocity name ="vservo104" joint ="joint104" kv="0.1"/>
    
    <motor joint="joint105" name ="torque105" ctrllimited="true" ctrlrange="-3.14 3.14" gear="1"/>
    <position name ="pservo105" joint ="joint105" kp="100"/>
    <velocity name ="vservo105" joint ="joint105" kv="0.1"/>
    
    <motor joint="joint106" name ="torque106" ctrllimited="true" ctrlrange="-3.14 3.14" gear="1"/>
    <position name ="pservo106" joint ="joint106" kp="100"/>
    <velocity name ="vservo106" joint ="joint106" kv="0.1"/>
    
    <motor joint="joint201" name ="torque201" ctrllimited="true" ctrlrange="-3.14 3.14" gear="1"/>
    <position name ="pservo201" joint ="joint201" kp="100"/>
    <velocity name ="vservo201" joint ="joint201" kv="0.1"/>
    
    <motor joint="joint202" name ="torque202" ctrllimited="true" ctrlrange="-3.14 3.14" gear="1"/>
    <position name ="pservo202" joint ="joint202" kp="100"/>
    <velocity name ="vservo202" joint ="joint202" kv="10"/>
    
    <motor joint="joint203" name ="torque203" ctrllimited="true" ctrlrange="-3.14 3.14" gear="1"/>
    <position name ="pservo203" joint ="joint203" kp="100"/>
    <velocity name ="vservo203" joint ="joint203" kv="0.1"/>
    
    <motor joint="joint204" name ="torque204" ctrllimited="true" ctrlrange="-3.14 3.14" gear="1"/>
    <position name ="pservo204" joint ="joint204" kp="100"/>
    <velocity name ="vservo204" joint ="joint204" kv="0.1"/>
    
    <motor joint="joint205" name ="torque205" ctrllimited="true" ctrlrange="-3.14 3.14" gear="1"/>
    <position name ="pservo205" joint ="joint205" kp="100"/>
    <velocity name ="vservo205" joint ="joint205" kv="0.1"/>
    
    <motor joint="joint206" name ="torque206" ctrllimited="true" ctrlrange="-3.14 3.14" gear="1"/>
    <position name ="pservo206" joint ="joint206" kp="100"/>
    <velocity name ="vservo206" joint ="joint206" kv="0.1"/>
    
  </actuator>



  </mujoco>
