<?xml version="1.0" encoding="utf-8"?>
<!-- This URDF was automatically created by SolidWorks to URDF Exporter! Originally created by Stephen Brawner (brawner@gmail.com) 
     Commit Version: 1.6.0-4-g7f85cfe  Build Version: 1.6.7995.38578
     For more information, please see http://wiki.ros.org/sw_urdf_exporter -->
     
     
      



<robot
  name="cx_arm">

 <mujoco>
        <compiler 
        meshdir="/home/u/CXDL/code/git/CXDL_ROS_mian/src/CXDL_ROS/cx_description/meshes/" 
        balanceinertia="true" 
        discardvisual="false" />
  </mujoco>
  
  
  <link 
  name="dummy">
</link>
<joint 
  name="dummy_joint" 
  type="fixed">
  <parent 
  link="dummy"/>
  <child 
  link="base_link"/>
</joint>



  <link
    name="base_link">
    <inertial>
      <origin
        xyz="1.3496E-11 2.9161E-11 -0.0009669"
        rpy="0 0 0" />
      <mass
        value="4.3273" />
      <inertia
        ixx="0.0093675"
        ixy="-2.4135E-11"
        ixz="1.8149E-12"
        iyy="0.0046459"
        iyz="3.9145E-12"
        izz="0.0088256" />
    </inertial>
    <visual>
      <origin
        xyz="0 0 0"
        rpy="0 0 0" />
      <geometry>
        <mesh
          filename="package://cx_description/meshes/base_link.STL" />
      </geometry>
      <material
        name="">
        <color
          rgba="0.89804 0.91765 0.92941 1" />
      </material>
    </visual>
    <collision>
      <origin
        xyz="0 0 0"
        rpy="0 0 0" />
      <geometry>
        <mesh
          filename="package://cx_description/meshes/base_link.STL" />
      </geometry>
    </collision>
  </link>
  <link
    name="Link101">
    <inertial>
      <origin
        xyz="6.59675766868129E-20 0.0311194583357993 -0.0313358876222972"
        rpy="0 0 0" />
      <mass
        value="0.308135455569499" />
      <inertia
        ixx="0.00036301532443775"
        ixy="-4.69010447040035E-20"
        ixz="1.32167773396478E-19"
        iyy="0.000311071590986095"
        iyz="-9.08288552069947E-05"
        izz="0.000308601623909284" />
    </inertial>
    <visual>
      <origin
        xyz="0 0 0"
        rpy="0 0 0" />
      <geometry>
        <mesh
          filename="package://cx_description/meshes/Link101.STL" />
      </geometry>
      <material
        name="">
        <color
          rgba="0.898039215686275 0.917647058823529 0.929411764705882 1" />
      </material>
    </visual>
    <collision>
      <origin
        xyz="0 0 0"
        rpy="0 0 0" />
      <geometry>
        <mesh
          filename="package://cx_description/meshes/Link101.STL" />
      </geometry>
    </collision>
  </link>
  <joint
    name="joint101"
    type="revolute">
    <origin
      xyz="0 0.241 0"
      rpy="-1.5708 -1.5708 0" />
    <parent
      link="base_link" />
    <child
      link="Link101" />
    <axis
      xyz="0 0 1" />
    <limit
      lower="-3.14"
      upper="3.14"
      effort="100"
      velocity="1" />
  </joint>
  <link
    name="Link102">
    <inertial>
      <origin
        xyz="-6.55817344874521E-11 -0.0474740262124326 -0.000349231545579994"
        rpy="0 0 0" />
      <mass
        value="2.69736870589475" />
      <inertia
        ixx="0.0030082793755842"
        ixy="3.60652165823711E-11"
        ixz="5.40640934375435E-11"
        iyy="0.0025464770034934"
        iyz="-4.37126407123363E-05"
        izz="0.00284907972609921" />
    </inertial>
    <visual>
      <origin
        xyz="0 0 0"
        rpy="0 0 0" />
      <geometry>
        <mesh
          filename="package://cx_description/meshes/Link102.STL" />
      </geometry>
      <material
        name="">
        <color
          rgba="0.898039215686275 0.917647058823529 0.929411764705882 1" />
      </material>
    </visual>
    <collision>
      <origin
        xyz="0 0 0"
        rpy="0 0 0" />
      <geometry>
        <mesh
          filename="package://cx_description/meshes/Link102.STL" />
      </geometry>
    </collision>
  </link>
  <joint
    name="joint102"
    type="revolute">
    <origin
      xyz="0 0 0"
      rpy="1.5707963267949 -1.5707963267949 0" />
    <parent
      link="Link101" />
    <child
      link="Link102" />
    <axis
      xyz="0 0 1" />
    <limit
      lower="-3.14"
      upper="3.14"
      effort="100"
      velocity="1" />
  </joint>
  <link
    name="Link103">
    <inertial>
      <origin
        xyz="0.00246382957139588 -8.55404549388039E-07 -0.110316621904337"
        rpy="0 0 0" />
      <mass
        value="0.542683241876569" />
      <inertia
        ixx="0.00195943955331105"
        ixy="1.06133506261008E-08"
        ixz="-0.000125539667263345"
        iyy="0.00182891010022251"
        iyz="-9.893584390285E-08"
        izz="0.000637941175022721" />
    </inertial>
    <visual>
      <origin
        xyz="0 0 0"
        rpy="0 0 0" />
      <geometry>
        <mesh
          filename="package://cx_description/meshes/Link103.STL" />
      </geometry>
      <material
        name="">
        <color
          rgba="0.898039215686275 0.917647058823529 0.929411764705882 1" />
      </material>
    </visual>
    <collision>
      <origin
        xyz="0 0 0"
        rpy="0 0 0" />
      <geometry>
        <mesh
          filename="package://cx_description/meshes/Link103.STL" />
      </geometry>
    </collision>
  </link>
  <joint
    name="joint103"
    type="revolute">
    <origin
      xyz="0 -0.310332732876607 0"
      rpy="3.14159265358979 1.5851 1.5707963267949" />
    <parent
      link="Link102" />
    <child
      link="Link103" />
    <axis
      xyz="0.014259082630836 0 0.999898334113287" />
    <limit
      lower="-3.14"
      upper="3.14"
      effort="100"
      velocity="1" />
  </joint>
  <link
    name="Link104">
    <inertial>
      <origin
        xyz="-0.00973407323337439 -0.0084158827012078 -2.83550796731369E-09"
        rpy="0 0 0" />
      <mass
        value="0.102218892732616" />
      <inertia
        ixx="3.56653856778505E-05"
        ixy="-7.71740478114551E-07"
        ixz="-7.75550468269683E-12"
        iyy="4.73824042215567E-05"
        iyz="-6.77614683121944E-12"
        izz="3.79479633157429E-05" />
    </inertial>
    <visual>
      <origin
        xyz="0 0 0"
        rpy="0 0 0" />
      <geometry>
        <mesh
          filename="package://cx_description/meshes/Link104.STL" />
      </geometry>
      <material
        name="">
        <color
          rgba="0.898039215686275 0.917647058823529 0.929411764705882 1" />
      </material>
    </visual>
    <collision>
      <origin
        xyz="0 0 0"
        rpy="0 0 0" />
      <geometry>
        <mesh
          filename="package://cx_description/meshes/Link104.STL" />
      </geometry>
    </collision>
  </link>
  <joint
    name="joint104"
    type="revolute">
    <origin
      xyz="0.0125 0 0"
      rpy="-1.5707963267949 0.0142595658712475 0" />
    <parent
      link="Link103" />
    <child
      link="Link104" />
    <axis
      xyz="0 0 1" />
    <limit
      lower="-3.14"
      upper="3.14"
      effort="100"
      velocity="1" />
  </joint>
  <link
    name="Link105">
    <inertial>
      <origin
        xyz="0.00133195040410225 -2.55653179266971E-07 -0.136429569933408"
        rpy="0 0 0" />
      <mass
        value="0.823764647767532" />
      <inertia
        ixx="0.000805500781618331"
        ixy="4.03918315855983E-09"
        ixz="-3.42170021300443E-05"
        iyy="0.000788137028091869"
        iyz="2.44637195319834E-08"
        izz="0.000520088856954166" />
    </inertial>
    <visual>
      <origin
        xyz="0 0 0"
        rpy="0 0 0" />
      <geometry>
        <mesh
          filename="package://cx_description/meshes/Link105.STL" />
      </geometry>
      <material
        name="">
        <color
          rgba="0.898039215686275 0.917647058823529 0.929411764705882 1" />
      </material>
    </visual>
    <collision>
      <origin
        xyz="0 0 0"
        rpy="0 0 0" />
      <geometry>
        <mesh
          filename="package://cx_description/meshes/Link105.STL" />
      </geometry>
    </collision>
  </link>
  <joint
    name="joint105"
    type="revolute">
    <origin
      xyz="-0.0154456341801033 -0.206469375499813 0"
      rpy="1.58505589266618 -1.5707963267949 0" />
    <parent
      link="Link104" />
    <child
      link="Link105" />
    <axis
      xyz="0 0 -1" />
    <limit
      lower="-3.14"
      upper="3.14"
      effort="100"
      velocity="1" />
  </joint>
  <link
    name="Link106">
    <inertial>
      <origin
        xyz="-0.0182055493076302 0.114974057116931 -0.00163960517877393"
        rpy="0 0 0" />
      <mass
        value="1.03484335525907" />
      <inertia
        ixx="0.00380609592755124"
        ixy="0.000103134452351464"
        ixz="-1.47083248339014E-06"
        iyy="0.000544517156882492"
        iyz="4.08943167849771E-05"
        izz="0.00341161962561141" />
    </inertial>
    <visual>
      <origin
        xyz="0 0 0"
        rpy="0 0 0" />
      <geometry>
        <mesh
          filename="package://cx_description/meshes/Link106.STL" />
      </geometry>
      <material
        name="">
        <color
          rgba="0.898039215686275 0.917647058823529 0.929411764705882 1" />
      </material>
    </visual>
    <collision>
      <origin
        xyz="0 0 0"
        rpy="0 0 0" />
      <geometry>
        <mesh
          filename="package://cx_description/meshes/Link106.STL" />
      </geometry>
    </collision>
  </link>
  <joint
    name="joint106"
    type="revolute">
    <origin
      xyz="0.0149932809362214 0 0.000448917328180309"
      rpy="1.58505589266618 0 0" />
    <parent
      link="Link105" />
    <child
      link="Link106" />
    <axis
      xyz="0 -0.0142590826308771 -0.999898334113287" />
    <limit
      lower="-3.14"
      upper="3.14"
      effort="100"
      velocity="1" />
  </joint>
  <link
    name="Link201">
    <inertial>
      <origin
        xyz="0 0 0"
        rpy="0 0 0" />
        <mass
        value="4.3273" />
      <inertia
        ixx="0.0093675"
        ixy="-2.4135E-11"
        ixz="1.8149E-12"
        iyy="0.0046459"
        iyz="3.9145E-12"
        izz="0.0088256" />
    </inertial>
    <visual>
      <origin
        xyz="0 0 0"
        rpy="0 0 0" />
      <geometry>
        <mesh
          filename="package://cx_description/meshes/Link201.STL" />
      </geometry>
      <material
        name="">
        <color
          rgba="1 1 1 1" />
      </material>
    </visual>
    <collision>
      <origin
        xyz="0 0 0"
        rpy="0 0 0" />
      <geometry>
        <mesh
          filename="package://cx_description/meshes/Link201.STL" />
      </geometry>
    </collision>
  </link>
  <joint
    name="joint201"
    type="revolute">
    <origin
      xyz="0 -0.241 0"
      rpy="-1.5708 -1.5708 0" />
    <parent
      link="base_link" />
    <child
      link="Link201" />
    <axis
      xyz="0 0 -1" />
    <limit
      lower="-3.14"
      upper="3.14"
      effort="100"
      velocity="1" />
  </joint>
  <link
    name="Link202">
    <inertial>
      <origin
        xyz="-6.55817899986033E-11 -0.0474740262124326 -0.00034923154558"
        rpy="0 0 0" />
      <mass
        value="2.69736870589475" />
      <inertia
        ixx="0.0030082793755842"
        ixy="3.60652161918021E-11"
        ixz="5.40640933467775E-11"
        iyy="0.0025464770034934"
        iyz="-4.37126407123364E-05"
        izz="0.00284907972609921" />
    </inertial>
    <visual>
      <origin
        xyz="0 0 0"
        rpy="0 0 0" />
      <geometry>
        <mesh
          filename="package://cx_description/meshes/Link202.STL" />
      </geometry>
      <material
        name="">
        <color
          rgba="0.898039215686275 0.917647058823529 0.929411764705882 1" />
      </material>
    </visual>
    <collision>
      <origin
        xyz="0 0 0"
        rpy="0 0 0" />
      <geometry>
        <mesh
          filename="package://cx_description/meshes/Link202.STL" />
      </geometry>
    </collision>
  </link>
  <joint
    name="joint202"
    type="revolute">
    <origin
      xyz="0 0 0"
      rpy="1.5707963267949 -1.5707963267949 0" />
    <parent
      link="Link201" />
    <child
      link="Link202" />
    <axis
      xyz="0 0 1" />
    <limit
      lower="-3.14"
      upper="3.14"
      effort="100"
      velocity="1" />
  </joint>
  <link
    name="Link203">
    <inertial>
      <origin
        xyz="-0.000244759458198421 -8.55404548999461E-07 -0.110036597964537"
        rpy="0 0 0" />
      <mass
        value="0.542683241876568" />
      <inertia
        ixx="0.00195247135863812"
        ixy="8.17826602777378E-09"
        ixz="-0.000157861047378578"
        iyy="0.0018289101002225"
        iyz="-9.91668310740805E-08"
        izz="0.000644909369695641" />
    </inertial>
    <visual>
      <origin
        xyz="0 0 0"
        rpy="0 0 0" />
      <geometry>
        <mesh
          filename="package://cx_description/meshes/Link203.STL" />
      </geometry>
      <material
        name="">
        <color
          rgba="0.898039215686275 0.917647058823529 0.929411764705882 1" />
      </material>
    </visual>
    <collision>
      <origin
        xyz="0 0 0"
        rpy="0 0 0" />
      <geometry>
        <mesh
          filename="package://cx_description/meshes/Link203.STL" />
      </geometry>
    </collision>
  </link>
  <joint
    name="joint203"
    type="revolute">
    <origin
      xyz="0 -0.310025563568998 0"
      rpy="3.14159265358979 1.609638767 1.5707963267949" />
    <parent
      link="Link202" />
    <child
      link="Link203" />
    <axis
      xyz="0.0388326272396109 0 0.999245729068516" />
    <limit
      lower="-3.14"
      upper="3.14"
      effort="100"
      velocity="1" />
  </joint>
  <link
    name="Link204">
    <inertial>
      <origin
        xyz="-0.0099379975328656 -0.00817407256148323 -2.9581451177485E-09"
        rpy="0 0 0" />
      <mass
        value="0.102218880136347" />
      <inertia
        ixx="3.56345354257467E-05"
        ixy="-4.82885098612412E-07"
        ixz="-6.96372006408195E-12"
        iyy="4.74132507072235E-05"
        iyz="-6.70597250520261E-12"
        izz="3.79479606986783E-05" />
    </inertial>
    <visual>
      <origin
        xyz="0 0 0"
        rpy="0 0 0" />
      <geometry>
        <mesh
          filename="package://cx_description/meshes/Link204.STL" />
      </geometry>
      <material
        name="">
        <color
          rgba="0.898039215686275 0.917647058823529 0.929411764705882 1" />
      </material>
    </visual>
    <collision>
      <origin
        xyz="0 0 0"
        rpy="0 0 0" />
      <geometry>
        <mesh
          filename="package://cx_description/meshes/Link204.STL" />
      </geometry>
    </collision>
  </link>
  <joint
    name="joint204"
    type="revolute">
    <origin
      xyz="0.0125 0 0"
      rpy="-1.5707963267949 0.0388423936269152 0" />
    <parent
      link="Link203" />
    <child
      link="Link204" />
    <axis
      xyz="0 0 1" />
    <limit
      lower="-3.14"
      upper="3.14"
      effort="100"
      velocity="1" />
  </joint>
  <link
    name="Link205">
    <inertial>
      <origin
        xyz="-0.00133197228224124 2.43084290037221E-07 -0.136429390874455"
        rpy="0 0 0" />
      <mass
        value="0.823765757378826" />
      <inertia
        ixx="0.000805510780988204"
        ixy="5.19532914660178E-09"
        ixz="3.421794436613E-05"
        iyy="0.000788145813374113"
        iyz="-2.32513647574758E-08"
        izz="0.00052008891850246" />
    </inertial>
    <visual>
      <origin
        xyz="0 0 0"
        rpy="0 0 0" />
      <geometry>
        <mesh
          filename="package://cx_description/meshes/Link205.STL" />
      </geometry>
      <material
        name="">
        <color
          rgba="0.898039215686275 0.917647058823529 0.929411764705882 1" />
      </material>
    </visual>
    <collision>
      <origin
        xyz="0 0 0"
        rpy="0 0 0" />
      <geometry>
        <mesh
          filename="package://cx_description/meshes/Link205.STL" />
      </geometry>
    </collision>
  </link>
  <joint
    name="joint205"
    type="revolute">
    <origin
      xyz="-0.0205160572972169 -0.206027333204814 0"
      rpy="1.60963872042181 -1.5707963267949 0" />
    <parent
      link="Link204" />
    <child
      link="Link205" />
    <axis
      xyz="0 0 -1" />
    <limit
      lower="-3.14"
      upper="3.14"
      effort="100"
      velocity="1" />
  </joint>
  <link
    name="Link206">
    <inertial>
      <origin
        xyz="0.018205543299802 0.11489896271364 -0.00446517812366447"
        rpy="0 0 0" />
      <mass
        value="1.03484379553031" />
      <inertia
        ixx="0.00380609629062902"
        ixy="-0.000103067264340546"
        ixz="4.00536682435992E-06"
        iyy="0.000548259380268447"
        iyz="0.000111298946484931"
        izz="0.00340787780040193" />
    </inertial>
    <visual>
      <origin
        xyz="0 0 0"
        rpy="0 0 0" />
      <geometry>
        <mesh
          filename="package://cx_description/meshes/Link206.STL" />
      </geometry>
      <material
        name="">
        <color
          rgba="0.898039215686275 0.917647058823529 0.929411764705882 1" />
      </material>
    </visual>
    <collision>
      <origin
        xyz="0 0 0"
        rpy="0 0 0" />
      <geometry>
        <mesh
          filename="package://cx_description/meshes/Link206.STL" />
      </geometry>
    </collision>
  </link>
  <joint
    name="joint206"
    type="revolute">
    <origin
      xyz="-0.0149932809362214 0 0.000448917328180309"
      rpy="1.60963872042181 0 0" />
    <parent
      link="Link205" />
    <child
      link="Link206" />
    <axis
      xyz="0 0.0388326272396134 0.999245729068516" />
    <limit
      lower="-3.14"
      upper="3.14"
      effort="100"
      velocity="1" />
  </joint>
</robot>
