<mujoco model="cx_description">
  <compiler angle="radian" meshdir="meshes/" autolimits="true"/>
  <asset>
    <mesh name="base_link" file="base_link.STL"/>
    <mesh name="Link101" file="Link101.STL"/>
    <mesh name="Link102" file="Link102.STL"/>
    <mesh name="Link103" file="Link103.STL"/>
    <mesh name="Link104" file="Link104.STL"/>
    <mesh name="Link105" file="Link105.STL"/>
    <mesh name="Link106" file="Link106.STL"/>
    <mesh name="Link201" file="Link201.STL"/>
    <mesh name="Link202" file="Link202.STL"/>
    <mesh name="Link203" file="Link203.STL"/>
    <mesh name="Link204" file="Link204.STL"/>
    <mesh name="Link205" file="Link205.STL"/>
    <mesh name="Link206" file="Link206.STL"/>
  </asset>
  <worldbody>
    <geom type="mesh" contype="0" conaffinity="0" group="1" density="0" rgba="0.898039 0.917647 0.929412 1" mesh="base_link"/>
    <geom type="mesh" rgba="0.898039 0.917647 0.929412 1" mesh="base_link"/>
    <body name="Link101" pos="0 0.241 0" quat="0.499998 -0.500002 -0.5 -0.5">
      <inertial pos="0 0.031119 -0.031336" quat="0.654197 -0.268376 0.268376 0.654197" mass="0.30814" diaginertia="0.000400672 0.00036302 0.000218998"/>
      <joint name="joint101" pos="0 0 0" axis="0 0 -1" range="-3.14 3.14"/>
      <geom type="mesh" contype="0" conaffinity="0" group="1" density="0" rgba="0.89804 0.91765 0.92941 1" mesh="Link101"/>
      <geom type="mesh" rgba="0.89804 0.91765 0.92941 1" mesh="Link101"/>
      <body name="Link102" quat="0.499998 -0.500002 0.5 0.5">
        <inertial pos="6.5582e-11 0.047474 -0.00034923" quat="0.755038 0.655681 0 0" mass="2.6974" diaginertia="0.0030083 0.00285529 0.00254031"/>
        <joint name="joint102" pos="0 0 0" axis="0 0 1" range="-3.14 3.14"/>
        <geom type="mesh" contype="0" conaffinity="0" group="1" density="0" rgba="0.89804 0.91765 0.92941 1" mesh="Link102"/>
        <geom type="mesh" rgba="0.89804 0.91765 0.92941 1" mesh="Link102"/>
        <body name="Link103" pos="0 0.31051 0" quat="0.499998 -0.5 -0.5 -0.500002">
          <inertial pos="0.00403786 -8.55405e-07 -0.110449" quat="0.999208 -3.77272e-05 0.0397992 7.12489e-05" mass="0.542683" diaginertia="0.00197126 0.00182891 0.000626121"/>
          <joint name="joint103" pos="0 0 0" axis="0 0 1" range="-3.14 3.14"/>
          <geom type="mesh" contype="0" conaffinity="0" group="1" density="0" rgba="0.898039 0.917647 0.929412 1" mesh="Link103"/>
          <geom type="mesh" rgba="0.898039 0.917647 0.929412 1" mesh="Link103"/>
          <body name="Link104" pos="0.0125 0 0" quat="0.707105 0.707108 0 0">
            <inertial pos="-0.010629 0.0077446 2.2742e-09" quat="0.488573 0.488573 0.511172 0.511172" mass="0.10826" diaginertia="5.26472e-05 4.1126e-05 4.02928e-05"/>
            <joint name="joint104" pos="0 0 0" axis="0 0 -1" range="-3.14 3.14"/>
            <geom type="mesh" contype="0" conaffinity="0" group="1" density="0" rgba="0.89804 0.91765 0.92941 1" mesh="Link104"/>
            <geom type="mesh" rgba="0.89804 0.91765 0.92941 1" mesh="Link104"/>
            <body name="Link105" pos="-0.0125 0.20712 0" quat="0.499998 -0.5 0.5 0.500002">
              <inertial pos="0.00133868 -2.52078e-07 -0.136878" quat="0.99827 4.69401e-05 0.0587985 3.19321e-05" mass="0.823765" diaginertia="0.000809548 0.00078814 0.000516044"/>
              <joint name="joint105" pos="0 0 0" axis="0 0 1" range="-3.14 3.14"/>
              <geom type="mesh" contype="0" conaffinity="0" group="1" density="0" rgba="0.898039 0.917647 0.929412 1" mesh="Link105"/>
              <geom type="mesh" rgba="0.898039 0.917647 0.929412 1" mesh="Link105"/>
              <body name="Link106" pos="0.015 0 0" quat="0.707105 0.707108 0 0">
                <inertial pos="-0.0147561 0.115479 -1.14344e-08" quat="0.707107 0.707107 0.00058135 0.00058135" mass="1.03484" diaginertia="0.00380935 0.0034122 0.000540677"/>
                <joint name="joint106" pos="0 0 0" axis="0 0 -1" range="-3.14 3.14"/>
                <geom type="mesh" contype="0" conaffinity="0" group="1" density="0" rgba="0.898039 0.917647 0.929412 1" mesh="Link106"/>
                <geom type="mesh" rgba="0.898039 0.917647 0.929412 1" mesh="Link106"/>
              </body>
            </body>
          </body>
        </body>
      </body>
    </body>
    <body name="Link201" pos="0 -0.241 0" quat="0.499998 -0.500002 -0.5 -0.5">
      <inertial pos="0 0.0311195 0.0313359" quat="0.654197 0.268376 -0.268376 0.654197" mass="0.308135" diaginertia="0.000400674 0.000363015 0.000218999"/>
      <joint name="joint201" pos="0 0 0" axis="0 0 -1" range="-3.14 3.14"/>
      <geom type="mesh" contype="0" conaffinity="0" group="1" density="0" rgba="0.898039 0.917647 0.929412 1" mesh="Link201"/>
      <geom type="mesh" rgba="0.898039 0.917647 0.929412 1" mesh="Link201"/>
      <body name="Link202" quat="0.499998 -0.500002 0.5 0.5">
        <inertial pos="6.55818e-11 0.047474 -0.000349232" quat="0.755038 0.655682 0 0" mass="2.69737" diaginertia="0.00300828 0.00285527 0.00254029"/>
        <joint name="joint202" pos="0 0 0" axis="0 0 -1" range="-3.14 3.14"/>
        <geom type="mesh" contype="0" conaffinity="0" group="1" density="0" rgba="0.898039 0.917647 0.929412 1" mesh="Link202"/>
        <geom type="mesh" rgba="0.898039 0.917647 0.929412 1" mesh="Link202"/>
        <body name="Link203" pos="0 0.31051 0" quat="0.499998 -0.5 -0.5 -0.500002">
          <inertial pos="0.0040379 -8.554e-07 -0.11045" quat="0.999208 -3.77286e-05 0.0397988 7.12193e-05" mass="0.54268" diaginertia="0.00197131 0.0018289 0.000626121"/>
          <joint name="joint203" pos="0 0 0" axis="0 0 -1" range="-3.14 3.14"/>
          <geom type="mesh" contype="0" conaffinity="0" group="1" density="0" rgba="0.89804 0.91765 0.92941 1" mesh="Link203"/>
          <geom type="mesh" rgba="0.89804 0.91765 0.92941 1" mesh="Link203"/>
          <body name="Link204" pos="0.0125 0 0" quat="0.707105 0.707108 0 0">
            <inertial pos="-0.0106289 0.00774461 2.53762e-09" quat="0.488573 0.488573 0.511172 0.511172" mass="0.108257" diaginertia="5.26468e-05 4.11257e-05 4.02926e-05"/>
            <joint name="joint204" pos="0 0 0" axis="0 0 -1" range="-3.14 3.14"/>
            <geom type="mesh" contype="0" conaffinity="0" group="1" density="0" rgba="0.898039 0.917647 0.929412 1" mesh="Link204"/>
            <geom type="mesh" rgba="0.898039 0.917647 0.929412 1" mesh="Link204"/>
            <body name="Link205" pos="-0.0125 0.20712 0" quat="0.499998 -0.5 0.5 0.500002">
              <inertial pos="-0.0013387 2.5208e-07 -0.13688" quat="0.99827 -4.69404e-05 -0.058799 3.19376e-05" mass="0.82376" diaginertia="0.000809545 0.00078814 0.000516045"/>
              <joint name="joint205" pos="0 0 0" axis="0 0 -1" range="-3.14 3.14"/>
              <geom type="mesh" contype="0" conaffinity="0" group="1" density="0" rgba="0.89804 0.91765 0.92941 1" mesh="Link205"/>
              <geom type="mesh" rgba="0.89804 0.91765 0.92941 1" mesh="Link205"/>
              <body name="Link206" pos="-0.015 0 0" quat="0.707105 0.707108 0 0">
                <inertial pos="0.014756 0.11548 1.1434e-08" quat="0.707107 0.707107 -0.000581359 -0.000581359" mass="1.0348" diaginertia="0.00380931 0.0034122 0.000540681"/>
                <joint name="joint206" pos="0 0 0" axis="0 0 1" range="-3.14 3.14"/>
                <geom type="mesh" contype="0" conaffinity="0" group="1" density="0" rgba="0.89804 0.91765 0.92941 1" mesh="Link206"/>
                <geom type="mesh" rgba="0.89804 0.91765 0.92941 1" mesh="Link206"/>
              </body>
            </body>
          </body>
        </body>
      </body>
    </body>
  </worldbody>


     <actuator>
    <motor joint="joint101" name ="torque101" gear = "1" ctrllimited="true" ctrlrange="-3.14 3.14"/>
    <position name ="position_servo101" joint ="joint101" kp="100"/>
    <velocity name ="velocity_servo101" joint ="joint101" kv="0.1"/>

    <motor joint="joint102" name ="torque102" gear = "1" ctrllimited="true" ctrlrange="-3.14 3.14"/>
    <position name ="position_servo102" joint ="joint102" kp="100"/>
    <velocity name ="velocity_servo102" joint ="joint102" kv="0.1"/>

    <motor joint="joint103" name ="torque103" gear = "1" ctrllimited="true" ctrlrange="-3.14 3.14"/>
    <position name ="position_servo103" joint ="joint103" kp="100"/>
    <velocity name ="velocity_servo103" joint ="joint103" kv="0.1"/>

    <motor joint="joint104" name ="torque104" gear = "1" ctrllimited="true" ctrlrange="-3.14 3.14"/>
    <position name ="position_servo104" joint ="joint104" kp="100"/>
    <velocity name ="velocity_servo104" joint ="joint104" kv="0.1"/>

    <motor joint="joint105" name ="torque105" gear = "1" ctrllimited="true" ctrlrange="-3.14 3.14"/>
    <position name ="position_servo105" joint ="joint105" kp="100"/>
    <velocity name ="velocity_servo105" joint ="joint105" kv="0.1"/>

    <motor joint="joint106" name ="torque106" gear = "1" ctrllimited="true" ctrlrange="-3.14 3.14"/>
    <position name ="position_servo106" joint ="joint106" kp="100"/>
    <velocity name ="velocity_servo106" joint ="joint106" kv="0.1"/>

    <motor joint="joint201" name ="torque201" gear = "1" ctrllimited="true" ctrlrange="-3.14 3.14"/>
    <position name ="position_servo201" joint ="joint201" kp="100"/>
    <velocity name ="velocity_servo201" joint ="joint201" kv="0.1"/>

    <motor joint="joint202" name ="torque202" gear = "1" ctrllimited="true" ctrlrange="-3.14 3.14"/>
    <position name ="position_servo202" joint ="joint202" kp="100"/>
    <velocity name ="velocity_servo202" joint ="joint202" kv="0.1"/>

    <motor joint="joint203" name ="torque203" gear = "1" ctrllimited="true" ctrlrange="-3.14 3.14"/>
    <position name ="position_servo203" joint ="joint203" kp="100"/>
    <velocity name ="velocity_servo203" joint ="joint203" kv="0.1"/>

    <motor joint="joint204" name ="torque204" gear = "1" ctrllimited="true" ctrlrange="-3.14 3.14"/>
    <position name ="position_servo204" joint ="joint204" kp="100"/>
    <velocity name ="velocity_servo204" joint ="joint204" kv="0.1"/>

    <motor joint="joint205" name ="torque205" gear = "1" ctrllimited="true" ctrlrange="-3.14 3.14"/>
    <position name ="position_servo205" joint ="joint205" kp="100"/>
    <velocity name ="velocity_servo205" joint ="joint205" kv="0.1"/>

    <motor joint="joint206" name ="torque206" gear = "1" ctrllimited="true" ctrlrange="-3.14 3.14"/>
    <position name ="position_servo206" joint ="joint206" kp="100"/>
    <velocity name ="velocity_servo206" joint ="joint206" kv="0.1"/>



    </actuator>



</mujoco>
